2022-11-13 21:31:36.741 | INFO     | __main__:main:91 - GuessNumberGame Server Start Successfully.
2022-11-13 21:31:40.830 | DEBUG    | __main__:route_ngg:22 - conn:<websockets.legacy.server.WebSocketServerProtocol object at 0x7fa612fe7670>
2022-11-13 21:31:42.208 | INFO     | __main__:route_ngg:32 - got a message:{"api":"list_open_room", "data":{"username":"zxz_test1","roomname":"我1"}}
2022-11-13 21:31:42.208 | INFO     | repository.crud:selectListByStatus:102 - [RoomCRUD::selectListByStatus]:sql=select * from room where status in (0, 1)
2022-11-13 21:31:42.212 | ERROR    | __main__:route_ngg:43 - [main.route_ngg] remote_address('101.64.140.35', 54494) errpr=Traceback (most recent call last):
  File "/root/code/pythoncode/PYProject/GuessNumberGame/src/main.py", line 36, in route_ngg
    res = handler(data_d["data"])
  File "/root/code/pythoncode/PYProject/GuessNumberGame/src/NGGService.py", line 38, in listOpenRoom
    rooms = [x.self2bo() for x in roomPOs]
  File "/root/code/pythoncode/PYProject/GuessNumberGame/src/NGGService.py", line 38, in <listcomp>
    rooms = [x.self2bo() for x in roomPOs]
  File "/root/code/pythoncode/PYProject/GuessNumberGame/src/./repository/RoomPO.py", line 37, in self2bo
    assert player != None # 应该只有注销用户 或者 数据库被篡改了才会出现这种情况
AssertionError

