2022-11-13 19:39:08.162 | INFO     | __main__:main:91 - GuessNumberGame Server Start Successfully.
2022-11-13 19:39:19.265 | DEBUG    | __main__:route_ngg:22 - conn:<websockets.legacy.server.WebSocketServerProtocol object at 0x7f09d6340670>
2022-11-13 19:39:25.100 | DEBUG    | __main__:route_ngg:22 - conn:<websockets.legacy.server.WebSocketServerProtocol object at 0x7f09d6340760>
2022-11-13 19:39:27.490 | DEBUG    | __main__:route_ngg:22 - conn:<websockets.legacy.server.WebSocketServerProtocol object at 0x7f09d6340f10>
2022-11-13 19:39:28.545 | DEBUG    | __main__:route_ngg:22 - conn:<websockets.legacy.server.WebSocketServerProtocol object at 0x7f09d636b3a0>
2022-11-13 19:40:57.076 | ERROR    | __main__:route_ngg:43 - [main.route_ngg] remote_address('101.64.140.35', 61522) errpr=Traceback (most recent call last):
  File "/root/code/pythoncode/PYProject/GuessNumberGame/src/main.py", line 31, in route_ngg
    async for message in conn:
  File "/root/miniconda3/envs/python39/lib/python3.9/site-packages/websockets/legacy/protocol.py", line 482, in __aiter__
    yield await self.recv()
  File "/root/miniconda3/envs/python39/lib/python3.9/site-packages/websockets/legacy/protocol.py", line 553, in recv
    await self.ensure_open()
  File "/root/miniconda3/envs/python39/lib/python3.9/site-packages/websockets/legacy/protocol.py", line 930, in ensure_open
    raise self.connection_closed_exc()
websockets.exceptions.ConnectionClosedError: received 1005 (no status code [internal]); then sent 1005 (no status code [internal])

