2022-11-13 21:18:16.547 | INFO     | __main__:main:91 - GuessNumberGame Server Start Successfully.
2022-11-13 21:18:20.930 | DEBUG    | __main__:route_ngg:22 - conn:<websockets.legacy.server.WebSocketServerProtocol object at 0x7f600ed3a790>
2022-11-13 21:18:22.904 | INFO     | __main__:route_ngg:32 - got a message:{"api":"create_room", "data":{"username":"zxz_test1","roomname":"我1"}}
2022-11-13 21:18:22.921 | INFO     | repository.crud:insert_without_id:78 - [RoomCRUD::insert_without_id]:sql1=insert into room(id,name,type,player_ids,history_game_ids,status) values ('我1', <ObjectType.NORMAL_ROOM: 40>, '[221]', '[]', 0);
sql2=select max(id) from room;
2022-11-13 21:18:22.934 | ERROR    | repository.crud:insert_without_id:84 - [RoomCRUD::insert_without_id] error=Traceback (most recent call last):
  File "/root/code/pythoncode/PYProject/GuessNumberGame/src/./repository/dbUtils.py", line 46, in execute_sqls_in_transaction
    cursor.execute(sql)
  File "/root/miniconda3/envs/python39/lib/python3.9/site-packages/pymysql/cursors.py", line 148, in execute
    result = self._query(query)
  File "/root/miniconda3/envs/python39/lib/python3.9/site-packages/pymysql/cursors.py", line 310, in _query
    conn.query(q)
  File "/root/miniconda3/envs/python39/lib/python3.9/site-packages/pymysql/connections.py", line 548, in query
    self._affected_rows = self._read_query_result(unbuffered=unbuffered)
  File "/root/miniconda3/envs/python39/lib/python3.9/site-packages/pymysql/connections.py", line 775, in _read_query_result
    result.read()
  File "/root/miniconda3/envs/python39/lib/python3.9/site-packages/pymysql/connections.py", line 1156, in read
    first_packet = self.connection._read_packet()
  File "/root/miniconda3/envs/python39/lib/python3.9/site-packages/pymysql/connections.py", line 725, in _read_packet
    packet.raise_for_error()
  File "/root/miniconda3/envs/python39/lib/python3.9/site-packages/pymysql/protocol.py", line 221, in raise_for_error
    err.raise_mysql_exception(self._data)
  File "/root/miniconda3/envs/python39/lib/python3.9/site-packages/pymysql/err.py", line 143, in raise_mysql_exception
    raise errorclass(errno, errval)
pymysql.err.ProgrammingError: (1064, "You have an error in your SQL syntax; check the manual that corresponds to your MySQL server version for the right syntax to use near '<ObjectType.NORMAL_ROOM: 40>, '[221]', '[]', 0)' at line 1")

During handling of the above exception, another exception occurred:

Traceback (most recent call last):
  File "/root/code/pythoncode/PYProject/GuessNumberGame/src/repository/crud.py", line 79, in insert_without_id
    res = execute_sqls_in_transaction([sql1, sql2])
  File "/root/code/pythoncode/PYProject/GuessNumberGame/src/./repository/dbUtils.py", line 54, in execute_sqls_in_transaction
    raise RuntimeError(e)
RuntimeError: (1064, "You have an error in your SQL syntax; check the manual that corresponds to your MySQL server version for the right syntax to use near '<ObjectType.NORMAL_ROOM: 40>, '[221]', '[]', 0)' at line 1")

